Workbook

Sheet Registro_Diario
A1: Fecha | B1: Mes | C1: N° Interno | D1: Patente | E1: Tipo Equipo | F1: Equipo | G1: Lugar/Área | H1: Horómetro Inicial | I1: Horómetro Final | J1: HD/KM | K1: Operador/Turno | L1: Observación
A2: 45957 | B2: Octubre | D2: UFJK-52 | E2: =+VLOOKUP(tbl_registro[[#This Row],[Patente]],Pivot_Equipos!$A$1:$E$39,3,FALSE) -> #N/A | F2: =+VLOOKUP(tbl_registro[[#This Row],[Tipo Equipo]],Pivot_Equipos!$C$1:$E$39,2,FALSE) -> #N/A | G2: Candelaria | H2: 2977 | I2: 3019 | J2: =I2-H2 -> 42 | K2: Freddy Méndez
A3: 45958 | B3: Octubre | D3: UFJK-52 | E3: =+VLOOKUP(tbl_registro[[#This Row],[Patente]],Pivot_Equipos!$A$1:$E$39,3,FALSE) -> #N/A | F3: =+VLOOKUP(tbl_registro[[#This Row],[Tipo Equipo]],Pivot_Equipos!$C$1:$E$39,2,FALSE) -> #N/A | G3: Candelaria | H3: 3019 | I3: 3030 | J3: =I3-H3 -> 11 | K3: Freddy Méndez
A4: 45959 | B4: Octubre | D4: UFJK-52 | E4: =+VLOOKUP(tbl_registro[[#This Row],[Patente]],Pivot_Equipos!$A$1:$E$39,3,FALSE) -> #N/A | F4: =+VLOOKUP(tbl_registro[[#This Row],[Tipo Equipo]],Pivot_Equipos!$C$1:$E$39,2,FALSE) -> #N/A | G4: Candelaria | H4: 3030 | I4: 3080 | J4: =I4-H4 -> 50 | K4: Freddy Méndez
A5: 45959 | B5: Octubre | C5: EX-6791 | D5: VRRF-41 | E5: =+VLOOKUP(tbl_registro[[#This Row],[Patente]],Pivot_Equipos!$A$1:$E$39,3,FALSE) -> FURGON PEUGEOT | F5: =+VLOOKUP(tbl_registro[[#This Row],[Tipo Equipo]],Pivot_Equipos!$C$1:$E$39,2,FALSE) -> Furgón | H5: 7150 | I5: 7222 | J5: =I5-H5 -> 72
A6: 45959 | B6: Octubre | C6: EX-6789 | D6: VFJK 42 | E6: =+VLOOKUP(tbl_registro[[#This Row],[Patente]],Pivot_Equipos!$A$1:$E$39,3,FALSE) -> CAMIONETA | F6: =+VLOOKUP(tbl_registro[[#This Row],[Tipo Equipo]],Pivot_Equipos!$C$1:$E$39,2,FALSE) -> Camioneta | H6: 3300 | I6: 3404 | J6: =I6-H6 -> 104
A7: 45959 | B7: Octubre | C7: EX-6787 | D7: VFJK 51 | E7: =+VLOOKUP(tbl_registro[[#This Row],[Patente]],Pivot_Equipos!$A$1:$E$39,3,FALSE) -> CAMIONETA | F7: =+VLOOKUP(tbl_registro[[#This Row],[Tipo Equipo]],Pivot_Equipos!$C$1:$E$39,2,FALSE) -> Camioneta | H7: 7400 | I7: 7497 | J7: =I7-H7 -> 97
A8: 45959 | B8: Octubre | C8: EX-6788 | D8: VFJK 52 | E8: =+VLOOKUP(tbl_registro[[#This Row],[Patente]],Pivot_Equipos!$A$1:$E$39,3,FALSE) -> CAMIONETA | F8: =+VLOOKUP(tbl_registro[[#This Row],[Tipo Equipo]],Pivot_Equipos!$C$1:$E$39,2,FALSE) -> Camioneta | H8: 3000 | I8: 3050 | J8: =I8-H8 -> 50
A9: 45959 | B9: Octubre | C9: EX-6790 | D9: VFJK 55 | E9: =+VLOOKUP(tbl_registro[[#This Row],[Patente]],Pivot_Equipos!$A$1:$E$39,3,FALSE) -> CAMIONETA | F9: =+VLOOKUP(tbl_registro[[#This Row],[Tipo Equipo]],Pivot_Equipos!$C$1:$E$39,2,FALSE) -> Camioneta | H9: 7500 | I9: 7535 | J9: =I9-H9 -> 35
A10: 45959 | B10: Octubre | C10: EX-6784 | D10: VFJK 56 | E10: =+VLOOKUP(tbl_registro[[#This Row],[Patente]],Pivot_Equipos!$A$1:$E$39,3,FALSE) -> CAMIONETA | F10: =+VLOOKUP(tbl_registro[[#This Row],[Tipo Equipo]],Pivot_Equipos!$C$1:$E$39,2,FALSE) -> Camioneta | H10: 4300 | I10: 4407 | J10: =I10-H10 -> 107
A11: 45959 | B11: Octubre | C11: EX-6786 | D11: VFJK 57 | E11: =+VLOOKUP(tbl_registro[[#This Row],[Patente]],Pivot_Equipos!$A$1:$E$39,3,FALSE) -> CAMIONETA | F11: =+VLOOKUP(tbl_registro[[#This Row],[Tipo Equipo]],Pivot_Equipos!$C$1:$E$39,2,FALSE) -> Camioneta | H11: 3255 | I11: 3368 | J11: =I11-H11 -> 113
A12: 45959 | B12: Octubre | C12: EX-6785 | D12: VFJK 61 | E12: =+VLOOKUP(tbl_registro[[#This Row],[Patente]],Pivot_Equipos!$A$1:$E$39,3,FALSE) -> CAMIONETA | F12: =+VLOOKUP(tbl_registro[[#This Row],[Tipo Equipo]],Pivot_Equipos!$C$1:$E$39,2,FALSE) -> Camioneta | H12: 4400 | I12: 4462 | J12: =I12-H12 -> 62
A13: 45957 | B13: Octubre | C13: EX-6792 | D13: 465 | E13: =+VLOOKUP(tbl_registro[[#This Row],[Patente]],Pivot_Equipos!$A$1:$E$39,3,FALSE) -> GRUA HORQUILLA 16 TON | F13: =+VLOOKUP(tbl_registro[[#This Row],[Tipo Equipo]],Pivot_Equipos!$C$1:$E$39,2,FALSE) -> Grua | H13: 291.3 | I13: 291.3 | J13: =I13-H13 -> 0
A14: 45957 | B14: Octubre | C14: EX-6793 | D14: 466 | E14: =+VLOOKUP(tbl_registro[[#This Row],[Patente]],Pivot_Equipos!$A$1:$E$39,3,FALSE) -> GRUA HORQUILLA 16 TON | F14: =+VLOOKUP(tbl_registro[[#This Row],[Tipo Equipo]],Pivot_Equipos!$C$1:$E$39,2,FALSE) -> Grua | H14: 272.8 | I14: 272.8 | J14: =I14-H14 -> 0
A15: 45957 | B15: Octubre | C15: EX-6794 | D15: 461 | E15: =+VLOOKUP(tbl_registro[[#This Row],[Patente]],Pivot_Equipos!$A$1:$E$39,3,FALSE) -> GRUA HORQUILLA 7 TON | F15: =+VLOOKUP(tbl_registro[[#This Row],[Tipo Equipo]],Pivot_Equipos!$C$1:$E$39,2,FALSE) -> Grua | H15: 64 | I15: 64 | J15: =I15-H15 -> 0
A16: 45957 | B16: Octubre | C16: EX-6795 | D16: 462 | E16: =+VLOOKUP(tbl_registro[[#This Row],[Patente]],Pivot_Equipos!$A$1:$E$39,3,FALSE) -> GRUA HORQUILLA 7 TON | F16: =+VLOOKUP(tbl_registro[[#This Row],[Tipo Equipo]],Pivot_Equipos!$C$1:$E$39,2,FALSE) -> Grua | H16: 200 | I16: 200 | J16: =I16-H16 -> 0
A17: 45957 | B17: Octubre | C17: EX-6796 | D17: 463 | E17: =+VLOOKUP(tbl_registro[[#This Row],[Patente]],Pivot_Equipos!$A$1:$E$39,3,FALSE) -> GRUA HORQUILLA 7 TON | F17: =+VLOOKUP(tbl_registro[[#This Row],[Tipo Equipo]],Pivot_Equipos!$C$1:$E$39,2,FALSE) -> Grua | H17: 158.6 | I17: 158.6 | J17: =I17-H17 -> 0
A18: 45957 | B18: Octubre | C18: EX-6797 | D18: 464 | E18: =+VLOOKUP(tbl_registro[[#This Row],[Patente]],Pivot_Equipos!$A$1:$E$39,3,FALSE) -> GRUA HORQUILLA 7 TON | F18: =+VLOOKUP(tbl_registro[[#This Row],[Tipo Equipo]],Pivot_Equipos!$C$1:$E$39,2,FALSE) -> Grua | H18: 151 | I18: 151 | J18: =I18-H18 -> 0
A19: 45957 | B19: Octubre | C19: EX-6798 | D19: 459 | E19: =+VLOOKUP(tbl_registro[[#This Row],[Patente]],Pivot_Equipos!$A$1:$E$39,3,FALSE) -> GRUA HORQUILLA 3 TON | F19: =+VLOOKUP(tbl_registro[[#This Row],[Tipo Equipo]],Pivot_Equipos!$C$1:$E$39,2,FALSE) -> Grua | H19: 118 | I19: 118 | J19: =I19-H19 -> 0
A20: 45957 | B20: Octubre | C20: EX-6799 | D20: 460 | E20: =+VLOOKUP(tbl_registro[[#This Row],[Patente]],Pivot_Equipos!$A$1:$E$39,3,FALSE) -> GRUA HORQUILLA 3 TON | F20: =+VLOOKUP(tbl_registro[[#This Row],[Tipo Equipo]],Pivot_Equipos!$C$1:$E$39,2,FALSE) -> Grua | H20: 151.1 | I20: 151.1 | J20: =I20-H20 -> 0
A21: 45957 | B21: Octubre | C21: EX-6800 | D21: 475 | E21: =+VLOOKUP(tbl_registro[[#This Row],[Patente]],Pivot_Equipos!$A$1:$E$39,3,FALSE) -> GRUA HORQUILLA 3.5 TON ELECTRICA | F21: =+VLOOKUP(tbl_registro[[#This Row],[Tipo Equipo]],Pivot_Equipos!$C$1:$E$39,2,FALSE) -> Grua | H21: 50 | I21: 50 | J21: =I21-H21 -> 0
A22: 45957 | B22: Octubre | C22: EX-6801 | D22: 467 | E22: =+VLOOKUP(tbl_registro[[#This Row],[Patente]],Pivot_Equipos!$A$1:$E$39,3,FALSE) -> GRUA HORQUILLA 2.5 TON ELECTRICA | F22: =+VLOOKUP(tbl_registro[[#This Row],[Tipo Equipo]],Pivot_Equipos!$C$1:$E$39,2,FALSE) -> Grua | H22: 195 | I22: 195 | J22: =I22-H22 -> 0
A23: 45958 | B23: Octubre | C23: EX-6792 | D23: 465 | E23: =+VLOOKUP(tbl_registro[[#This Row],[Patente]],Pivot_Equipos!$A$1:$E$39,3,FALSE) -> GRUA HORQUILLA 16 TON | F23: =+VLOOKUP(tbl_registro[[#This Row],[Tipo Equipo]],Pivot_Equipos!$C$1:$E$39,2,FALSE) -> Grua | H23: 291.3 | I23: 292 | J23: =I23-H23 -> 0.7
A24: 45958 | B24: Octubre | C24: EX-6793 | D24: 466 | E24: =+VLOOKUP(tbl_registro[[#This Row],[Patente]],Pivot_Equipos!$A$1:$E$39,3,FALSE) -> GRUA HORQUILLA 16 TON | F24: =+VLOOKUP(tbl_registro[[#This Row],[Tipo Equipo]],Pivot_Equipos!$C$1:$E$39,2,FALSE) -> Grua | H24: 272.8 | I24: 275 | J24: =I24-H24 -> 2.2
... A42: 45959 | B42: Octubre | C42: EX-6801 | D42: 467 | E42: =+VLOOKUP(tbl_registro[[#This Row],[Patente]],Pivot_Equipos!$A$1:$E$39,3,FALSE) -> GRUA HORQUILLA 2.5 TON ELECTRICA | F42: =+VLOOKUP(tbl_registro[[#This Row],[Tipo Equipo]],Pivot_Equipos!$C$1:$E$39,2,FALSE) -> Grua | H42: 196.7 | I42: 197 | J42: =I42-H42 -> 0.3
A43: 45959 | B43: Octubre | C43: EX6832 | D43: VCYC-50 | E43: =+VLOOKUP(tbl_registro[[#This Row],[Patente]],Pivot_Equipos!$A$1:$E$39,3,FALSE) -> TRACTO CAMIONES 28TN (RAMPLA) | F43: =+VLOOKUP(tbl_registro[[#This Row],[Tipo Equipo]],Pivot_Equipos!$C$1:$E$39,2,FALSE) -> Tracto Camión | H43: 5500 | I43: 5584 | J43: =I43-H43 -> 84
A44: 45959 | B44: Octubre | C44: EX-6804 | D44: VCYC-53 | E44: =+VLOOKUP(tbl_registro[[#This Row],[Patente]],Pivot_Equipos!$A$1:$E$39,3,FALSE) -> TRACTO CAMIONES 28TN (RAMPLA) | F44: =+VLOOKUP(tbl_registro[[#This Row],[Tipo Equipo]],Pivot_Equipos!$C$1:$E$39,2,FALSE) -> Tracto Camión | H44: 6750 | I44: 6805 | J44: =I44-H44 -> 55
A45: 45959 | B45: Octubre | C45: EX-6833 | D45: VCYC-51 | E45: =+VLOOKUP(tbl_registro[[#This Row],[Patente]],Pivot_Equipos!$A$1:$E$39,3,FALSE) -> TRACTO PARA CAMA BAJA 25 y 40 TON | F45: =+VLOOKUP(tbl_registro[[#This Row],[Tipo Equipo]],Pivot_Equipos!$C$1:$E$39,2,FALSE) -> Tracto Camión | H45: 9250 | I45: 9337 | J45: =I45-H45 -> 87
A46: 45959 | B46: Octubre | C46: EX-6834 | D46: VCYC-52 | E46: =+VLOOKUP(tbl_registro[[#This Row],[Patente]],Pivot_Equipos!$A$1:$E$39,3,FALSE) -> TRACTO PARA CAMA BAJA 25 y 40 TON | F46: =+VLOOKUP(tbl_registro[[#This Row],[Tipo Equipo]],Pivot_Equipos!$C$1:$E$39,2,FALSE) -> Tracto Camión | H46: 7480 | I46: 7543 | J46: =I46-H46 -> 63
A47: 45959 | B47: Octubre | C47: EX-6802 | D47: HHBL-29 | E47: =+VLOOKUP(tbl_registro[[#This Row],[Patente]],Pivot_Equipos!$A$1:$E$39,3,FALSE) -> TRACTO PARA CAMA BAJA 60 y 100 TON | F47: =+VLOOKUP(tbl_registro[[#This Row],[Tipo Equipo]],Pivot_Equipos!$C$1:$E$39,2,FALSE) -> Tracto Camión | H47: 227800 | I47: 227834 | J47: =I47-H47 -> 34
A48: 45959 | B48: Octubre | C48: EX-6836 | D48: VFZG 96 | E48: =+VLOOKUP(tbl_registro[[#This Row],[Patente]],Pivot_Equipos!$A$1:$E$39,3,FALSE) -> CAMIÓN 10 TON | F48: =+VLOOKUP(tbl_registro[[#This Row],[Tipo Equipo]],Pivot_Equipos!$C$1:$E$39,2,FALSE) -> Camión Plano | H48: 5950 | I48: 6014 | J48: =I48-H48 -> 64
A49: 45960 | B49: Octubre | C49: EX-6791 | D49: VRRF-41 | E49: =+VLOOKUP(tbl_registro[[#This Row],[Patente]],Pivot_Equipos!$A$1:$E$39,3,FALSE) -> FURGON PEUGEOT | F49: =+VLOOKUP(tbl_registro[[#This Row],[Tipo Equipo]],Pivot_Equipos!$C$1:$E$39,2,FALSE) -> Furgón | H49: 7222 | I49: 7250 | J49: =I49-H49 -> 28
A50: 45960 | B50: Octubre | C50: EX-6789 | D50: VFJK 42 | E50: =+VLOOKUP(tbl_registro[[#This Row],[Patente]],Pivot_Equipos!$A$1:$E$39,3,FALSE) -> CAMIONETA | F50: =+VLOOKUP(tbl_registro[[#This Row],[Tipo Equipo]],Pivot_Equipos!$C$1:$E$39,2,FALSE) -> Camioneta | H50: 3404 | I50: 3404 | J50: =I50-H50 -> 0
A51: 45960 | B51: Octubre | C51: EX-6787 | D51: VFJK 51 | E51: =+VLOOKUP(tbl_registro[[#This Row],[Patente]],Pivot_Equipos!$A$1:$E$39,3,FALSE) -> CAMIONETA | F51: =+VLOOKUP(tbl_registro[[#This Row],[Tipo Equipo]],Pivot_Equipos!$C$1:$E$39,2,FALSE) -> Camioneta | H51: 7497 | I51: 7551 | J51: =I51-H51 -> 54
A52: 45960 | B52: Octubre | C52: EX-6788 | D52: VFJK 52 | E52: =+VLOOKUP(tbl_registro[[#This Row],[Patente]],Pivot_Equipos!$A$1:$E$39,3,FALSE) -> CAMIONETA | F52: =+VLOOKUP(tbl_registro[[#This Row],[Tipo Equipo]],Pivot_Equipos!$C$1:$E$39,2,FALSE) -> Camioneta | H52: 3050 | I52: 3070 | J52: =I52-H52 -> 20
A53: 45960 | B53: Octubre | C53: EX-6790 | D53: VFJK 55 | E53: =+VLOOKUP(tbl_registro[[#This Row],[Patente]],Pivot_Equipos!$A$1:$E$39,3,FALSE) -> CAMIONETA | F53: =+VLOOKUP(tbl_registro[[#This Row],[Tipo Equipo]],Pivot_Equipos!$C$1:$E$39,2,FALSE) -> Camioneta | H53: 7535 | I53: 7550 | J53: =I53-H53 -> 15
A54: 45960 | B54: Octubre | C54: EX-6784 | D54: VFJK 56 | E54: =+VLOOKUP(tbl_registro[[#This Row],[Patente]],Pivot_Equipos!$A$1:$E$39,3,FALSE) -> CAMIONETA | F54: =+VLOOKUP(tbl_registro[[#This Row],[Tipo Equipo]],Pivot_Equipos!$C$1:$E$39,2,FALSE) -> Camioneta | H54: 4407 | I54: 4461 | J54: =I54-H54 -> 54
... A80: 45963 | B80: Noviembre | C80: EX-6785 | D80: VFJK 61 | E80: =+VLOOKUP(tbl_registro[[#This Row],[Patente]],Pivot_Equipos!$A$1:$E$39,3,FALSE) -> CAMIONETA | F80: =+VLOOKUP(tbl_registro[[#This Row],[Tipo Equipo]],Pivot_Equipos!$C$1:$E$39,2,FALSE) -> Camioneta | H80: 4646 | I80: 4692 | J80: =I80-H80 -> 46
A81: 45960 | B81: Octubre | C81: EX-6792 | D81: 465 | E81: =+VLOOKUP(tbl_registro[[#This Row],[Patente]],Pivot_Equipos!$A$1:$E$39,3,FALSE) -> GRUA HORQUILLA 16 TON | F81: =+VLOOKUP(tbl_registro[[#This Row],[Tipo Equipo]],Pivot_Equipos!$C$1:$E$39,2,FALSE) -> Grua | H81: 293.1 | I81: 299.1 | J81: =I81-H81 -> 6
A82: 45960 | B82: Octubre | C82: EX-6793 | D82: 466 | E82: =+VLOOKUP(tbl_registro[[#This Row],[Patente]],Pivot_Equipos!$A$1:$E$39,3,FALSE) -> GRUA HORQUILLA 16 TON | F82: =+VLOOKUP(tbl_registro[[#This Row],[Tipo Equipo]],Pivot_Equipos!$C$1:$E$39,2,FALSE) -> Grua | H82: 275 | I82: 278.8 | J82: =I82-H82 -> 3.8
...

Sheet Hoja2
A1: Fecha | B1: (Todas) | D1: Horas efectivas de trabajo | P1: Operador/Turno | Q1: (Todas)
A2: Mes | B2: Octubre | P2: Mes | Q2: (Todas)
A3: Operador/Turno | B3: (Todas)
A4: Equipo | B4: Grua | P4: Suma de HD/KM | Q4: Etiquetas de columna
P5: Patente | Q5: 45957 | R5: 45958 | S5: 45959 | T5: 45960 | U5: 45961 | V5: 45962 | W5: 45963 | X5: Total general
A6: Patente | B6: Suma de HD/KM | P6: 465 | Q6: 1.3 | R6: 0.7 | S6: 1.1 | T6: 6 | U6: 0 | V6: 0 | W6: 0 | X6: 9.1
A7: 459 | B7: 7.6 | P7: Total general | Q7: 1.3 | R7: 0.7 | S7: 1.1 | T7: 6 | U7: 0 | V7: 0 | W7: 0 | X7: 9.1
A8: 460 | B8: 4.9
A9: 461 | B9: 2.9
A10: 462 | B10: 4.1
A11: 463 | B11: 13
A12: 464 | B12: 8.1
A13: 465 | B13: 9.1
A14: 466 | B14: 8.8
A15: 467 | B15: 5
A16: 475 | B16: 4
A17: Total general | B17: 67.5
A23: Operador/Turno | B23: (Todas)
A24: Mes | B24: Octubre
A26: Suma de HD/KM | B26: Etiquetas de columna
A27: Patente | B27: 461 | C27: Total general
A28: 45957 | B28: 2 | C28: 2
A29: 45958 | B29: 0.2 | C29: 0.2
A30: 45959 | B30: 0 | C30: 0
A31: 45960 | B31: 0.7 | C31: 0.7
A32: 45961 | B32: 0 | C32: 0
A33: Total general | B33: 2.9 | C33: 2.9

Sheet Tabla Resume
H4: Mes | I4: =+Hoja2!$B$2 -> Octubre | P4: Mes | Q4: =+Hoja2!B24 -> Octubre
B5: =+Hoja2!$B$15 -> 5 | H5: Fecha | I5: =+Hoja2!$B$1 -> (Todas) | L5: =+GETPIVOTDATA("HD/KM",Hoja2!$A$26) -> 2.9 | P5: Tipo de Equipo
H6: Operador | I6: =+Hoja2!$B$3 -> (Todas) | P6: Operador | Q6: =+Hoja2!B23 -> (Todas)
H7: Tipo de Equipo | I7: =+Hoja2!$B$4 -> Grua | P7: Equipo | Q7: =+Hoja2!B27 -> 461
B28: Tabla Resume Horómetro diario
B30: Operador/Turno | C30: (Todas)
B31: Mes | C31: Octubre
B32: Equipo | C32: (Todas)
B34: Suma de HD/KM | C34: Etiquetas de columna
B35: Patente | C35: 45957 | D35: 45958 | E35: 45959 | F35: 45960 | G35: 45961 | H35: Total general
B36: 459 | C36: 2 | D36: 0.6 | E36: 0.4 | F36: 1 | G36: 3.6 | H36: 7.6
B37: 460 | C37: 2.1 | D37: 0.4 | E37: 0.9 | F37: 0.8 | G37: 0.7 | H37: 4.9
B38: 461 | C38: 2 | D38: 0.2 | E38: 0 | F38: 0.7 | G38: 0 | H38: 2.9
B39: 462 | C39: 1 | D39: 0.5 | E39: 0 | F39: 0.1 | G39: 2.5 | H39: 4.1
B40: 463 | C40: 1.6 | D40: 4.1 | E40: 0.1 | F40: 7.2 | G40: 0 | H40: 13
B41: 464 | C41: 2 | D41: 0.5 | E41: 2.9 | F41: 0.2 | G41: 2.5 | H41: 8.1
B42: 465 | C42: 1.3 | D42: 0.7 | E42: 1.1 | F42: 6 | G42: 0 | H42: 9.1
B43: 466 | C43: 2.8 | D43: 2.2 | E43: 0 | F43: 3.8 | G43: 0 | H43: 8.8
B44: 467 | C44: 2 | D44: 1.7 | E44: 0.3 | F44: 1 | G44: 0 | H44: 5
B45: Total general | C45: 16.8 | D45: 10.9 | E45: 5.7 | F45: 20.8 | G45: 9.3 | H45: 63.5
B49: Horómetro Actual
B52: Mes | C52: Octubre
B53: Fecha | C53: 45961
B55: Patente | C55: Suma de Horómetro Final
B56: 459 | C56: 123.6
B57: GRUA HORQUILLA 3 TON | C57: 123.6
B58: 460 | C58: 153.9
B59: GRUA HORQUILLA 3 TON | C59: 153.9
B60: 461 | C60: 64.9
B61: GRUA HORQUILLA 7 TON | C61: 64.9
B62: 462 | C62: 203.1
B63: GRUA HORQUILLA 7 TON | C63: 203.1
B64: 463 | C64: 170
B65: GRUA HORQUILLA 7 TON | C65: 170
B66: 464 | C66: 236.6
B67: GRUA HORQUILLA 7 TON | C67: 236.6
B68: 465 | C68: 299.1
B69: GRUA HORQUILLA 16 TON | C69: 299.1
B70: 466 | C70: 278.8
B71: GRUA HORQUILLA 16 TON | C71: 278.8
...

Sheet Consumo Adblue
A1: PATENTE | B1: N°INTERNO | C1: TIPO DE EQUIPO | D1: EQUIPO | E1: Fecha de Carga de Adblue
A3: VRRF-41 | B3: EX-6791 | C3: FURGON PEUGEOT | D3: Furgón
A4: VF.ZG-96 | B4: EX-6794 | C4: CAMIÓN PLANO MERCEDEZ BENZ | D4: Camión Plano
A5: CV.YC-50 | B5: EX-6832 | C5: TRACTO CAMIÓN MERCEDEZ BENZ | D5: Tracto Camión
A6: VC.YC-52 | B6: EX-6833 | C6: TRACTO CAMIÓN MERCEDEZ BENZ | D6: Tracto Camión
A7: VC.YC-53 | B7: EX-6805 | C7: TRACTO CAMIÓN MERCEDEZ BENZ | D7: Tracto Camión
A8: HH.BL-29 | B8: EX-6806 | C8: TRACTO CAMIÓN MERCEDEZ BENZ | D8: Tracto Camión
A9: PX.GC-26 | B9: N/A | C9: RAMPLA GOREN 28 TON | D9: Rampla
A10: PX.HY-62 | B10: N/A | C10: RAMPLA GOREN 28 TON | D10: Rampla
A11: PX.JP-71 | B11: N/A | C11: SEMI REMOLQUE PLANO GOREN 25 TON | D11: Cama Baja
A12: PX.GC-25 | B12: N/A | C12: SEMI REMOLQUE PLANO GOREN 45 TON | D12: Cama Baja
A13: PX.JP-72 | B13: N/A | C13: SEMI REMOLQUE PLANO GOREN 60 TON | D13: Cama Baja
A14: GR.DK-96 | B14: N/A | C14: SEMI REMOLQUE PLANO GOREN 60 TON | D14: Cama Baja
A15: JJ.97-99 | B15: N/A | C15: SEMI REMOLQUE PLANO GOREN 100 TON | D15: Cama Baja
A16: 465 | B16: EX-6792 | C16: GRUA HORQUILLA 16 TON | D16: Grua
A17: 466 | B17: EX-6793 | C17: GRUA HORQUILLA 16 TON | D17: Grua
A18: 461 | B18: EX-6794 | C18: GRUA HORQUILLA 7 TON | D18: Grua
A19: 462 | B19: EX-6795 | C19: GRUA HORQUILLA 7 TON | D19: Grua
A20: 463 | B20: EX-6796 | C20: GRUA HORQUILLA 7 TON | D20: Grua
A21: 464 | B21: EX-6797 | C21: GRUA HORQUILLA 7 TON | D21: Grua
A22: 459 | B22: EX-6798 | C22: GRUA HORQUILLA 3 TON | D22: Grua
A23: 460 | B23: EX-6799 | C23: GRUA HORQUILLA 3 TON | D23: Grua
A24: 448 | B24: EX-6800 | C24: GRUA HORQUILLA 3.5 TON ELECTRICA | D24: Grua
A25: 475 | C25: GRUA HORQUILLA 3.5 TON ELECTRICA | D25: Grua
A26: 467 | B26: EX-6801 | C26: GRUA HORQUILLA 2.5 TON ELECTRICA | D26: Grua
A27: UFJK-52 | C27: CAMIONETA | D27: Camioneta
A28: VCYC-50 | B28: EX6832 | C28: TRACTO CAMIONES 28TN (RAMPLA) | D28: Tracto Camión
A29: VCYC-53 | B29: EX-6804 | C29: TRACTO CAMIONES 28TN (RAMPLA) | D29: Tracto Camión
A30: VCYC-51 | B30: EX-6833 | C30: TRACTO PARA CAMA BAJA 25 y 40 TON | D30: Tracto Camión
A31: VCYC-52 | B31: EX-6834 | C31: TRACTO PARA CAMA BAJA 25 y 40 TON | D31: Tracto Camión
A32: HHBL-29 | B32: EX-6802 | C32: TRACTO PARA CAMA BAJA 60 y 100 TON | D32: Tracto Camión
A33: VFZG 96 | B33: EX-6836 | C33: CAMIÓN 10 TON | D33: Camión Plano
A34: VFJK 42 | B34: EX-6789 | C34: CAMIONETA | D34: Camioneta
A35: VFJK 51 | B35: EX-6787 | C35: CAMIONETA | D35: Camioneta
A36: VFJK 52 | B36: EX-6788 | C36: CAMIONETA | D36: Camioneta
A37: VFJK 55 | B37: EX-6790 | C37: CAMIONETA | D37: Camioneta
A38: VFJK 56 | B38: EX-6784 | C38: CAMIONETA | D38: Camioneta
A39: VFJK 57 | B39: EX-6786 | C39: CAMIONETA | D39: Camioneta
A40: VFJK 61 | B40: EX-6785 | C40: CAMIONETA | D40: Camioneta

Sheet Pivot_Equipos
A1: PATENTE | B1: N°INTERNO | C1: TIPO DE EQUIPO | D1: EQUIPO | E1: ÁREA | H1: LISTADO DE PERSONAL | I1: CARGO | J1: EQUIPO | K1: PATENTE | L1: N°INTERNO | M1: ÁREA
A2: VRRF-41 | B2: EX-6791 | C2: FURGON PEUGEOT | D2: Furgón | E2: B. Principal (candelaria). | H2: FURGON PEUGEOT
A3: VF.ZG-96 | B3: EX-6794 | C3: CAMIÓN PLANO MERCEDEZ BENZ | D3: Camión Plano | E3: Laguna seca (candelaria). | H3: CAMIÓN PLANO MERCEDEZ BENZ
A4: CV.YC-50 | B4: EX-6832 | C4: TRACTO CAMIÓN MERCEDEZ BENZ | D4: Tracto Camión | E4: Laguna seca (candelaria). | H4: TRACTO CAMIÓN MERCEDEZ BENZ
A5: VC.YC-52 | B5: EX-6833 | C5: TRACTO CAMIÓN MERCEDEZ BENZ | D5: Tracto Camión | E5: Laguna seca (candelaria). | H5: TRACTO CAMIÓN MERCEDEZ BENZ
A6: VC.YC-53 | B6: EX-6805 | C6: TRACTO CAMIÓN MERCEDEZ BENZ | D6: Tracto Camión | E6: Laguna seca (candelaria). | H6: TRACTO CAMIÓN MERCEDEZ BENZ
A7: HH.BL-29 | B7: EX-6806 | C7: TRACTO CAMIÓN MERCEDEZ BENZ | D7: Tracto Camión | E7: Laguna seca (candelaria). | H7: TRACTO CAMIÓN MERCEDEZ BENZ
A8: PXGC-26 | B8: N/A | C8: RAMPLA GOREN 28 TON | D8: Rampla | E8: Laguna seca (candelaria). | H8: RAMPLA GOREN 28 TON
A9: PX.HY-62 | B9: N/A | C9: RAMPLA GOREN 28 TON | D9: Rampla | E9: Laguna seca (candelaria). | H9: RAMPLA GOREN 28 TON
A10: PX.JP-71 | B10: N/A | C10: SEMI REMOLQUE PLANO GOREN 25 TON | D10: Cama Baja | E10: Laguna seca (candelaria). | H10: SEMI REMOLQUE PLANO GOREN 25 TON
A11: PX.GC-25 | B11: N/A | C11: SEMI REMOLQUE PLANO GOREN 45 TON | D11: Cama Baja | E11: Laguna seca (candelaria). | H11: SEMI REMOLQUE PLANO GOREN 45 TON
A12: PX.JP-72 | B12: N/A | C12: SEMI REMOLQUE PLANO GOREN 60 TON | D12: Cama Baja | E12: Laguna seca (candelaria). | H12: SEMI REMOLQUE PLANO GOREN 60 TON
A13: GR.DK-96 | B13: N/A | C13: SEMI REMOLQUE PLANO GOREN 60 TON | D13: Cama Baja | E13: Laguna seca (candelaria). | H13: SEMI REMOLQUE PLANO GOREN 60 TON
A14: JJ.97-99 | B14: N/A | C14: SEMI REMOLQUE PLANO GOREN 100 TON | D14: Cama Baja | E14: Laguna seca (candelaria). | H14: SEMI REMOLQUE PLANO GOREN 100 TON
A15: 465 | B15: EX-6792 | C15: GRUA HORQUILLA 16 TON | D15: Grua | E15: Patio PRV (candelaria). | H15: GRUA HORQUILLA 16 TON
A16: 466 | B16: EX-6793 | C16: GRUA HORQUILLA 16 TON | D16: Grua | E16: Patio PC02 (candelaria). | H16: GRUA HORQUILLA 16 TON
A17: 461 | B17: EX-6794 | C17: GRUA HORQUILLA 7 TON | D17: Grua | E17: Puerto punta Padrones. | H17: GRUA HORQUILLA 7 TON
A18: 462 | B18: EX-6795 | C18: GRUA HORQUILLA 7 TON | D18: Grua | E18: Planta (PAC). | H18: GRUA HORQUILLA 7 TON
A19: 463 | B19: EX-6796 | C19: GRUA HORQUILLA 7 TON | D19: Grua | E19: Cargo directo (candelaria). | H19: GRUA HORQUILLA 7 TON
A20: 464 | B20: EX-6797 | C20: GRUA HORQUILLA 7 TON | D20: Grua | E20: Patio PC01 (candelaria). | H20: GRUA HORQUILLA 7 TON
A21: 459 | B21: EX-6798 | C21: GRUA HORQUILLA 3 TON | D21: Grua | E21: Planta (PAC). | H21: GRUA HORQUILLA 3 TON
A22: 460 | B22: EX-6799 | C22: GRUA HORQUILLA 3 TON | D22: Grua | E22: Patio PC01 (candelaria). | H22: GRUA HORQUILLA 3 TON
A23: 448 | B23: EX-6800 | C23: GRUA HORQUILLA 3.5 TON ELECTRICA | D23: Grua | E23: B. Principal (candelaria). | H23: GRUA HORQUILLA 3.5 TON ELECTRICA
A24: 475 | C24: GRUA HORQUILLA 3.5 TON ELECTRICA | D24: Grua | E24: B. Principal (candelaria). | H24: GRUA HORQUILLA 3.5 TON ELECTRICA
A25: 467 | B25: EX-6801 | C25: GRUA HORQUILLA 2.5 TON ELECTRICA | D25: Grua | E25: Suspel PC01 (candelaria). | H25: GRUA HORQUILLA 2.5 TON ELECTRICA
A26: VCYC-50 | B26: EX-6832 | C26: TRACTO CAMIONES 28TN (RAMPLA) | D26: Tracto Camión
A27: VCYC-53 | B27: EX-6804 | C27: TRACTO CAMIONES 28TN (RAMPLA) | D27: Tracto Camión
A28: VCYC-51 | B28: EX-6833 | C28: TRACTO PARA CAMA BAJA 25 y 40 TON | D28: Tracto Camión
A29: VCYC-52 | B29: EX-6834 | C29: TRACTO PARA CAMA BAJA 25 y 40 TON | D29: Tracto Camión
A30: HHBL-29 | B30: EX-6802 | C30: TRACTO PARA CAMA BAJA 60 y 100 TON | D30: Tracto Camión
A31: VFZG 96 | B31: EX-6836 | C31: CAMIÓN 10 TON | D31: Camión Plano
A32: VFJK 42 | B32: EX-6789 | C32: CAMIONETA | D32: Camioneta
A33: VFJK 51 | B33: EX-6787 | C33: CAMIONETA | D33: Camioneta
A34: VFJK 52 | B34: EX-6788 | C34: CAMIONETA | D34: Camioneta
A35: VFJK 55 | B35: EX-6790 | C35: CAMIONETA | D35: Camioneta
A36: VFJK 56 | B36: EX-6784 | C36: CAMIONETA | D36: Camioneta
A37: VFJK 57 | B37: EX-6786 | C37: CAMIONETA | D37: Camioneta
A38: VFJK 61 | B38: EX-6785 | C38: CAMIONETA | D38: Camioneta

Sheet Listado de Operadores
A1: N° | B1: Rut | C1: Nombre | D1: Cargo | E1: Equipo | F1: Equipo 1 | G1: Equipo 2 | H1: Mail
A2: 1 | B2: 17773565-5 | C2: Nicolas Andres Alvarez Andia | D2: Conductor Escolta | E2: Camioneta | F2: Camioneta | G2: Camioneta | H2: =+VLOOKUP(Tabla6[[#This Row],[Rut]],Hoja1!$1:$1048576,9,FALSE) -> nicolas_alvarez_chile@hotmail.com
A3: 2 | B3: 9.636.994-8 | C3: Adolfo Del Transito Barraza Cortes | D3: Conductor Cama Baja | E3: Tracto | F3: Cama baja | G3: Camioneta | H3: =+VLOOKUP(Tabla6[[#This Row],[Rut]],Hoja1!$1:$1048576,9,FALSE) -> barraza4020adolfo@gmail.com
A4: 3 | B4: 11.821.221-5 | C4: Jesus Lenin Brizuela Cotaipi | D4: Operador Camión Rampla | E4: Tracto | F4: Rampla | G4: Camioneta | H4: =+VLOOKUP(Tabla6[[#This Row],[Rut]],Hoja1!$1:$1048576,9,FALSE) -> lenin.brizuela@gmail.com
A5: 4 | B5: 15.611.414-6 | C5: Javier Guillermo Castelli Beltran | D5: Conductor Cama Baja | E5: Tracto | F5: Cama baja | G5: Camioneta | H5: =+VLOOKUP(Tabla6[[#This Row],[Rut]],Hoja1!$1:$1048576,9,FALSE) -> javi30guiller@gmail.com
A6: 5 | B6: 10.880.227-8 | C6: Franklin Wilfredo Coello Salazar | D6: Conductor Cama Baja | E6: Tracto | F6: Cama baja | G6: Camioneta | H6: =+VLOOKUP(Tabla6[[#This Row],[Rut]],Hoja1!$1:$1048576,9,FALSE) -> fcoello1966@hotmail.com
A7: 6 | B7: 19.124.982-8 | C7: Jordan Gerardo Diaz Morales | D7: Conductor Escolta | E7: Camioneta | F7: Camioneta | G7: Camioneta | H7: =+VLOOKUP(Tabla6[[#This Row],[Rut]],Hoja1!$1:$1048576,9,FALSE) -> diaz.jordan2013@gmail.com
A8: 7 | B8: 15.043.880-2 | C8: Jorge Antonio Ibacache Jimenez | D8: Conductor Escolta | E8: Camioneta | F8: Camioneta | G8: Camioneta | H8: =+VLOOKUP(Tabla6[[#This Row],[Rut]],Hoja1!$1:$1048576,9,FALSE) -> koky-jimenez20@hotmail.com
A9: 8 | B9: 10.078.119-0 | C9: Johny Angel Miranda Huine | D9: Operador Camion Plano | E9: Camión | F9: 10 TN | G9: Camioneta | H9: =+VLOOKUP(Tabla6[[#This Row],[Rut]],Hoja1!$1:$1048576,9,FALSE) -> johnyangelm@gmail.com
A10: 9 | B10: 10.924.663-8 | C10: Marco Miguel Muñoz Cordero | D10: Conductor Cama Baja | E10: Tracto | F10: Cama baja | G10: Camioneta | H10: =+VLOOKUP(Tabla6[[#This Row],[Rut]],Hoja1!$1:$1048576,9,FALSE) -> emeliymauro2015@gmail.com
A11: 10 | B11: 13.181.927-7 | C11: Sandro Mauricio Puelles Puelles | D11: Operador Camión Rampla | E11: Tracto | F11: Rampla | G11: Camioneta | H11: =+VLOOKUP(Tabla6[[#This Row],[Rut]],Hoja1!$1:$1048576,9,FALSE) -> smppka@gmail.com
A12: 11 | B12: 12.444.078-5 | C12: Enzo Salomon Reyes Pereira | D12: Conductor Escolta | E12: Camioneta | F12: Camioneta | G12: Camioneta | H12: =+VLOOKUP(Tabla6[[#This Row],[Rut]],Hoja1!$1:$1048576,9,FALSE) -> salomonpereira72@gmail.com
A13: 12 | B13: 21.314.854-0 | C13: Rafael Antonio Rivera Muñoz | D13: Conductor Escolta | E13: Camioneta | F13: Camioneta | G13: Camioneta | H13: =+VLOOKUP(Tabla6[[#This Row],[Rut]],Hoja1!$1:$1048576,9,FALSE) -> rr.antonio2003@gmail.com
... A23: 22 | B23: 17.191.399-3 | C23: Bastian Valdivia Valdivia | D23: Operador Bodega | E23: Grua Horquilla | F23: Grua Horquilla | G23: Camioneta | H23: =+VLOOKUP(Tabla6[[#This Row],[Rut]],Hoja1!$1:$1048576,9,FALSE) -> bastian.alfredo.valdivia@gmail.com
A24: 23 | B24: 15.869.605-3 | C24: Ramon Rojas Cortes | D24: Operador Bodega | E24: Grua Horquilla | F24: Grua Horquilla | G24: Camioneta | H24: ramonmario2827@gmail.com
A25: 24 | B25: 16.833.666-7 | C25: Alfredo Cabrera Cabrera | D25: Supervisor | E25: Camioneta | F25: Camioneta | G25: Camioneta | H25: acabrera@rfp-logistica.cl
A26: 25 | B26: 16.056.906-9 | C26: Hugo Calderon Sanchez | D26: Administrador de Contrato | E26: Camioneta | F26: Camioneta | G26: Camioneta | H26: hcalderon@rfp-logistica.cl
A27: 26 | B27: 12.328.191-8 | C27: José Cofre Campos | D27: Supervisor | E27: Camioneta | F27: Camioneta | G27: Camioneta | H27: =+VLOOKUP(Tabla6[[#This Row],[Rut]],Hoja1!$1:$1048576,9,FALSE) -> guillecofre@hotmail.com
A28: 27 | B28: 15.951.205-3 | C28: Freddy Mendez Moncada | D28: Supervisor Senior | E28: Camioneta | F28: Camioneta | G28: Camioneta | H28: =+VLOOKUP(Tabla6[[#This Row],[Rut]],Hoja1!$1:$1048576,9,FALSE) -> fmendez@rfp-logistica.cl
A29: 28 | B29: 17.328.537-k | C29: Abraham Peña Cares | D29: Supervisor | E29: Camioneta | F29: Camioneta | G29: Camioneta | H29: =+VLOOKUP(Tabla6[[#This Row],[Rut]],Hoja1!$1:$1048576,9,FALSE) -> abraham.sotraser@gmail.com
A30: 29 | B30: 16.865.077-9 | C30: Claudio Pino Santiagos | D30: Supervisor Senior | E30: Camioneta | F30: Camioneta | G30: Camioneta | H30: clpino@rfp-logistica.cl
A31: 30 | B31: 13.531.194-4 | C31: Ramón Cristian Rojas Zuñiga | D31: Analista de Inventario | E31: Camioneta | F31: Camioneta | G31: Camioneta | H31: rrojas@rfp-logistica.cl
B32: 19.738.580-4 | C32: Sederik Olmos Robledo | D32: Operador Bodega | E32: Camioneta | F32: Camioneta | G32: Camioneta | H32: =+VLOOKUP(Tabla6[[#This Row],[Rut]],Hoja1!$1:$1048576,9,FALSE) -> sk.olmosr@gmail.com
B33: 20.152.313-3 | C33: Alan Vega Caceres | D33: Operador Bodega | E33: Camioneta | F33: Camioneta | G33: Camioneta | H33: =+VLOOKUP(Tabla6[[#This Row],[Rut]],Hoja1!$1:$1048576,9,FALSE) -> alan.vega@hotmail.com
C34: Luis Ocampo | D34: Operador Bodega | E34: Grua Horquilla | F34: Grua Horquilla | H34: =+VLOOKUP(Tabla6[[#This Row],[Rut]],Hoja1!$1:$1048576,9,FALSE) -> #N/A
H35: =+VLOOKUP(Tabla6[[#This Row],[Rut]],Hoja1!$1:$1048576,9,FALSE) -> #N/A

Sheet Hoja1
A1: Empleado - Número de Documento | B1: Empleado - Apellido | C1: Empleado - Segundo Apellido | D1: Empleado - Nombre | E1: Empleado - Fecha de Nacimiento | F1: Empleado - Nacionalidad | G1: Empleado - Sexo | H1: Empleado - Teléfono Particular | I1: Empleado - Email Personal | J1: Empleado - Comuna | K1: Empleado - Dirección | L1: Trabajo - Fecha Ingreso Compañía | M1: Trabajo - Cargo | N1: Licencia
A2: 23.588.827-0 | B2: Albarracin | C2: Rojas | D2: Walter Antonio | E2: 28544 | F2: Chilena | G2: M | H2: 995227182 | I2: late_7815@outlook.com | J2: Copiapó | K2: Psje. Violeta # 51 | L2: 45812 | M2: Operador Romana
A3: 17773565-5 | B3: Alvarez | C3: Andia | D3: Nicolas Andres | E3: 33455 | F3: Chilena | G3: M | H3: 992536150 | I3: nicolas_alvarez_chile@hotmail.com | J3: Copiapó | K3: Calle Fundo Palermo #795 | L3: 45889 | M3: Conductor Escolta | N3: B
A4: 16.132.487-6 | B4: Arenas | C4: Fernandez | D4: Victor Manuel | E4: 31311 | F4: Chilena | G4: M | H4: 961087287 | I4: varenasf.1985@gmail.com | J4: Copiapó | K4: Carretera El Inca # 86 | L4: 45809 | M4: Operador Bodega | N4: B-D
A5: 9.636.994-8 | B5: Barraza | C5: Cortes | D5: Adolfo Del Transito | E5: 23274 | F5: Chilena | G5: M | H5: 985045448 | I5: barraza4020adolfo@gmail.com | J5: Copiapó | K5: Huascar # 1515 | L5: 45810 | M5: Conductor Cama Baja | N5: A2-B
A6: 11.821.221-5 | B6: Brizuela | C6: Cotaipi | D6: Jesus Lenin | E6: 25927 | F6: Chilena | G6: M | H6: 948088334 | I6: lenin.brizuela@gmail.com | J6: Copiapó | K6: Salitrera Chucumata # 845 | L6: 45810 | M6: Operador Camión Rampla | N6: A5-B-D
A7: 16.833.666-7 | B7: Cabrera | C7: Cabrera | D7: Alfredo | E7: 31171 | F7: Chilena | G7: M | H7: 939512825 | J7: Copiapó | K7: Amadeo de Lard #1940 | L7: 45901 | M7: Supervisor | N7: B-D
A8: 20.153.217-5 | B8: Cabrera | C8: Mallega | D8: Ignacio Fabian | E8: 36649 | F8: Chilena | G8: M | H8: 929945438 | I8: nacho4071@gmail.com | J8: Copiapó | K8: Los Carreras # 1131 | L8: 45809 | M8: Operador Romana
A9: 16.056.906-9 | B9: Calderon | C9: Sanchez | D9: Hugo | E9: 1985-0911 | F9: Chilena | G9: M | H9: 975228501 | I9: hugo_calderon_sanchez@hotmail.com | J9: Copiapó | K9: Los Carreras 1131 Depto 1412 | L9: 45922 | M9: Administrador de Contrato | N9: A4-D-A2
A10: 17.055.065-k | B10: Campusano | C10: Contreras | D10: Andrea Pilar | E10: 32428 | F10: Chilena | G10: F | H10: 995607324 | I10: a.campusano74@gmail.com | J10: Copiapó | K10: Rio Pulido # 3 | L10: 45810 | M10: Ayudante de Bodega
A11: 15.611.414-6 | B11: Castelli | C11: Beltran | D11: Javier Guillermo | E11: 30615 | F11: Chilena | G11: M | H11: 971081392 | I11: javi30guiller@gmail.com | J11: Copiapó | K11: Calle Vicente Zegers # 6603 | L11: 45809 | M11: Conductor Cama Baja | N11: A5-A2-B-D
A12: 16.559.297-2 | B12: Castillo | C12: Araya | D12: Cristian Rodrigo | E12: 31598 | F12: Chilena | G12: M | H12: 956073428 | I12: cristiancastilloaraya@hotmail.com | K12: Calle Romulo Mandeola #495 | L12: 45915 | M12: Operador Bodega
A13: 12.618.569-3 | B13: Cepeda | C13: Zapata | D13: Juan de la Cruz | E13: 27377 | F13: Chilena | G13: M | H13: 939377919 | I13: jdelacruz14121974@gmail.com | J13: Copiapó | K13: FRAY GIL DE SAN NICOLAS #3267 | L13: 45902 | M13: Operador Bodega
A14: 10.880.227-8 | B14: Coello | C14: Salazar | D14: Franklin Wilfredo | E14: 24300 | F14: Chilena | G14: M | H14: 996523086 | I14: fcoello1966@hotmail.com | J14: Copiapó | K14: Salitrera Solferino N° 1731 | L14: 45809 | M14: Conductor Cama Baja | N14: B-A2-D
A15: 12.328.191-8 | B15: Cofre | C15: Campos | D15: Jose Guillermo | E15: 26955 | F15: Chilena | G15: M | H15: 972722128 | I15: guillecofre@hotmail.com | J15: Copiapó | K15: Araucaria Parana # 720 | L15: 45809 | M15: Supervisor | N15: A3-A5-B-D
A16: 11.725.332-5 | B16: Contreras | C16: Diaz | D16: Luis Alberto | E16: 26093 | F16: Chilena | G16: M | H16: 920310370 | I16: luiscontrerasdiaz1971@gmail.com | J16: Copiapó | K16: Calcopirita N°1593, Villa Los Minerales | L16: 45826 | M16: Ayudante de Bodega
A17: 17.465.179-5 | B17: Cortes | C17: Perez | D17: Francisco David | E17: 32805 | F17: Chilena | G17: M | H17: 56991997746 | I17: fd.cortes.perez@gmail.com | J17: Copiapó | K17: Francisco de Aguirre #78 | L17: 45866 | M17: Operador Bodega
A18: 10.056.323-1 | B18: Diaz | C18: Briceño | D18: Heriberto Antonio Del Carmen | E18: 23846 | F18: Chilena | G18: M | H18: 990624447 | I18: hdhdiazb@gmail.com | J18: Copiapó | K18: Calle Moises Arce # 454 | L18: 45813 | M18: Operador Romana
A19: 19.124.982-8 | B19: Diaz | C19: Morales | D19: Jordan Gerardo | E19: 34852 | F19: Chilena | G19: M | H19: 977841844 | I19: diaz.jordan2013@gmail.com | J19: Copiapó | K19: Avenida El Polamar # 1121, Dpto 109 Torre B | L19: 45809 | M19: Conductor Escolta | N19: A3-A5-B
A20: 19.927.158-k | B20: Fernandez | C20: Castro | D20: Jose Ignacio | E20: 36029 | F20: Chilena | G20: M | H20: 963481510 | I20: joseignaciofernandez.c@gmail.com | J20: Copiapó | K20: Hernán Sánchez Aliste # 6238 | L20: 45813 | M20: Operador Romana
A21: 16.559.088-0 | B21: Galleguillos | C21: Silva | D21: Raul Mauricio | E21: 1986-23-09 | F21: Chilena | G21: M | H21: 973298095 | I21: silvagalleguillos7@gmail.com | J21: Copiapó | K21: Maria Delfina Hidalgo #378, Colonias Extranjeras | L21: 45922 | M21: Operador Bodega
A22: 19.352.586-5 | B22: Guerrero | C22: Guerrero | D22: Joaquin Andres | E22: 35130 | F22: Chilena | G22: M | H22: 985153794 | I22: juacopsgg@gmail.com | J22: Copiapó | K22: Salitrera Nebraska #1950 | L22: 45810 | M22: Ayudante de Bodega
A23: 16.250.192-5 | B23: Hidalgo | C23: Iriarte | D23: Andres Patricio | E23: 31685 | F23: Chilena | G23: M | H23: 948633999 | I23: andres.hidalgo.iriarte@gmail.com | J23: Copiapó | K23: Pasaje Bach # 2590 | L23: 45809 | M23: Operador Romana
A24: 14.150.731-1 | B24: Hurtado | C24: Galvez | D24: Waldo Andres | E24: 29642 | F24: Chilena | G24: M | H24: 985361925 | I24: ironmaiden24@gmail.com | J24: Copiapó | K24: Isabel Peña Morales # 4563 | L24: 45813 | M24: Ayudante de Bodega
A25: 15.043.880-2 | B25: Ibacache | C25: Jimenez | D25: Jorge Antonio | E25: 30091 | F25: Chilena | G25: M | H25: 961547001 | I25: koky-jimenez20@hotmail.com | J25: Copiapó | K25: Salitrera Tres Marias # 1835 | L25: 45813 | M25: Conductor Escolta | N25: A4-A2-B
A26: 18.709.406-2 | B26: Illanes | C26: Navarrete | D26: Martin Matias Ignacio | E26: 34294 | F26: Chilena | G26: M | H26: 56992622627 | I26: martinillanes93@gmail.com | J26: Copiapó | K26: Osorno #2498 | L26: 45875 | M26: Operador Bodega
A27: 18.138.417-4 | B27: Julio | C27: Escalera | D27: Franco | E27: 33757 | F27: Chilena | G27: M | H27: 961188334 | I27: francko.julio@gmail.com | J27: Copiapó | K27: Avenida El Palomar # 1121 | L27: 45915 | M27: Operador Bodega | N27: B-D
A28: 14.098.924-k | B28: Lagunas | C28: Toledo | D28: Williams Hugo Aaron | E28: 27618 | F28: Chilena | G28: M | H28: 977619012 | I28: williams.laguna.toledo@gmail.com | J28: Copiapó | K28: SALITRERA JOSEFINA #2490 | L28: 45870 | M28: Operador Bodega | N28: B-D
A29: 24.238.781-3 | B29: Lopez | D29: Wilbert | E29: 30079 | F29: Boliviana | G29: M | H29: 962626193 | I29: lopezlopezwilbert2@gmail.com | J29: Copiapó | K29: Calle Balmaceda # 646 | L29: 45809 | M29: Operador Bodega | N29: B-D
A30: 25.740.232-0 | B30: Marcano | D30: Carlos Adolfo | E30: 31064 | F30: Venezolana | G30: M | H30: 947165499 | I30: ca.marcano@hotmail.com | J30: Copiapó | K30: Leonidas Perez # 3450, Dpto. 108 Torre 3 | L30: 45810 | M30: Operador Romana
A31: 15.951.205-3 | B31: Mendez | C31: Moncada | D31: Freddy Adam | E31: 31058 | F31: Chilena | G31: M | H31: 945739288 | I31: fmendez@rfp-logistica.cl | J31: Copiapó | K31: Panamericana Norte # 836 | L31: 45915 | M31: Supervisor Senior | N31: B
A32: 10.078.119-0 | B32: Miranda | C32: Huine | D32: Johny Angel | E32: 24032 | F32: Chilena | G32: M | H32: 982552004 | I32: johnyangelm@gmail.com | J32: Copiapó | K32: Calle Quidora Nº 1285 | L32: 45810 | M32: Operador Camion Plano | N32: A4-B
A33: 19.352.660-8 | B33: Molina | C33: Cortés | D33: Carlos Andres | E33: 35124 | F33: Chilena | G33: M | H33: 978539145 | I33: 96molinaca@gmail.com | J33: Copiapó | K33: Bartolina Chillimaco #1139 | L33: 45810 | M33: Ayudante de Bodega
A34: 17.330.900-7 | B34: Morales | C34: Guerrero | D34: Alvaro | E34: 32811 | F34: Chilena | G34: M | H34: 972838441 | I34: alvaromoralesg30@gmail.com | J34: Copiapó | K34: Pasaje Caleta Horcón # 937 | L34: 45915 | M34: Operador Bodega
A35: 10.924.663-8 | B35: Muñoz | C35: Cordero | D35: Marco Miguel | E35: 24942 | F35: Chilena | G35: M | H35: 940239701 | I35: emeliymauro2015@gmail.com | J35: Copiapó | K35: Ana Vallejos # 5543 | L35: 45809 | M35: Conductor Cama Baja | N35: B-A2-D
A36: 20.153.082-2 | B36: Navarro | C36: Castro | D36: Rafael Josafat | E36: 36606 | F36: Chilena | G36: M | H36: 967085250 | I36: r.navarro.c2103@gmail.com | J36: Copiapó | K36: Einten # 1128 | L36: 45812 | M36: Operador Romana
A37: 17.773.972-3 | B37: Olave | C37: Lira | D37: Sebastian Andres | E37: 33433 | F37: Chilena | G37: M | H37: 950174278 | I37: seba.lira01@gmail.com | J37: Copiapó | K37: Miguel Gallo 943 | L37: 45866 | M37: Operador Bodega
A38: 20.990.084-k | B38: Olivares | C38: Carvajal | D38: Kristhina Constanza | E38: 37321 | F38: Chilena | G38: F | H38: 963657692 | I38: kristhinaolivares6@gmail.com | J38: Copiapó | K38: Manganita #2071 | L38: 45810 | M38: Administrativo Coordinador
A39: 19.451.518-9 | B39: Olivares | C39: Urzúa | D39: Pablo Andres | E39: 35544 | F39: Chilena | G39: M | H39: 957862536 | I39: pabloaou_12@hotmail.com | J39: Caldera | K39: El Cisne # 681 | L39: 45809 | M39: Operador Romana
A40: 19.738.580-4 | B40: Olmos | C40: Roblero | D40: Sederik Alejandro | E40: 35905 | F40: Chilena | G40: M | H40: 966706213 | I40: sk.olmosr@gmail.com | J40: Copiapó | K40: Yumbel # 630 | L40: 45810 | M40: Operador Bodega | N40: B-D
...

Sheet Registro
A1: equipo | B1: caracteristica | C1: Proovedor | D1: patente | E1: N° Interno | F1: Categoria | J1: 45957 | K1: 45958 | L1: 45959 | M1: 45960 | N1: 45961 | O1: 45962 | P1: 45963 | Q1: 45964
A2: FURGON | C2: ECONORET | D2: VFRF 41 | E2: EX-6791 | F2: PEUGEOT | L2: 7222 | M2: 7250 | N2: 7250 | O2: 7250 | P2: 7250 | Q2: 7452
A3: CAMIONETA | B3: 1,05 TON | C3: ECONORET | D3: VFJK 42 | E3: EX-6789 | F3: FORD | G3: RANGER | H3: 2025 | I3: ARRRIENDO ECONORENT | L3: 3404 | M3: 3404 | N3: 3509.5 | O3: 3509.5 | P3: 3509.5 | Q3: 3575
A4: CAMIONETA | B4: 1,05 TON | C4: ECONORET | D4: VFJK 51 | E4: EX-6787 | F4: FORD | G4: RANGER | H4: 2025 | I4: ARRRIENDO ECONORENT | K4: 9182 | L4: 7497 | M4: 7551 | N4: 7836 | O4: 7910 | P4: 8016 | Q4: 8117.7
A5: CAMIONETA | B5: 1,05 TON | C5: ECONORET | D5: VFJK 52 | E5: EX-6788 | F5: FORD | G5: RANGER | H5: 2025 | I5: ARRRIENDO ECONORENT | L5: 3050 | M5: 3070 | N5: 3070 | O5: 3263 | P5: 3265.2
A6: CAMIONETA | B6: 1,05 TON | C6: ECONORET | D6: VFJK 55 | E6: EX-6790 | F6: FORD | G6: RANGER | H6: 2025 | I6: ARRRIENDO ECONORENT | L6: 7535 | M6: 7550 | N6: 7550 | O6: 7550 | P6: 7550
A7: CAMIONETA | B7: 1,05 TON | C7: ECONORET | D7: VFJK 56 | E7: EX-6784 | F7: FORD | G7: RANGER | H7: 2025 | I7: ARRRIENDO ECONORENT | L7: 4407 | M7: 4461 | N7: 4699 | O7: 4732 | P7: 4732 | Q7: 4872
A8: CAMIONETA | B8: 1,05 TON | C8: ECONORET | D8: VFJK 57 | E8: EX-6786 | F8: FORD | G8: RANGER | H8: 2025 | I8: ARRRIENDO ECONORENT | L8: 3368 | M8: 3389 | N8: 3412.5 | O8: 3412.5 | P8: 3412.5
A9: CAMIONETA | B9: 1,05 TON | C9: ECONORET | D9: VFJK 61 | E9: EX-6785 | F9: FORD | G9: RANGER | H9: 2025 | I9: ARRRIENDO ECONORENT | L9: 4462 | M9: 4523 | N9: 4593 | O9: 4646 | P9: 4692 | Q9: 4523
A10: GRUA HORQUILLA (Diesel ) | B10: 16 TON | C10: Comamo (PRV) | D10: 465 | E10: EX-6792 | F10: HELI | G10: CPCD160-C2Z-06 | H10: 2025 | I10: MEGA CENTRO (COMACO) | J10: 291.3 | K10: 292 | L10: 293.1 | M10: 299.1 | N10: 299.1 | O10: 299.1 | P10: 288.1
A11: GRUA HORQUILLA (Diesel ) | B11: 16 TON | C11: Comamo (PC 2) | D11: 466 | E11: EX-6793 | F11: HELI | G11: CPCD160-C2Z-06 | H11: 2025 | I11: MEGA CENTRO (COMACO) | J11: 272.8 | K11: 275 | L11: 275 | M11: 278.8 | N11: 278.8 | O11: 278.8 | P11: 278.8
A12: GRUA HORQUILLA (Diesel ) | B12: 7 TON | C12: Comamo (Puerto) | D12: 461 | E12: EX-6794 | F12: HELI | G12: CPCD70-CU1G3 | H12: 2023 | I12: MEGA CENTRO (COMACO) | J12: 64 | K12: 64.2 | L12: 64.2 | M12: 64.9 | N12: 64.9 | O12: 64.9 | P12: 64.9 | Q12: 64.9
A13: GRUA HORQUILLA (Diesel ) | B13: 7 TON | C13: Comamo (Planta PAC) | D13: 462 | E13: EX-6795 | F13: HELI | G13: CPCD70-CU1G3 | H13: 2024 | I13: MEGA CENTRO (COMACO) | J13: 200 | K13: 200.5 | L13: 200.5 | M13: 200.6 | N13: 203.1 | O13: 203.5 | P13: 203.5
A14: GRUA HORQUILLA (Diesel ) | B14: 7 TON | C14: Comamo (PC 1) | D14: 463 | E14: EX-6796 | F14: HELI | G14: CPCD70-CU1G3 | H14: 2024 | I14: MEGA CENTRO (COMACO) | J14: 158.6 | K14: 162.7 | L14: 162.8 | M14: 170 | N14: 170 | O14: 170 | P14: 170
A15: GRUA HORQUILLA (Diesel ) | B15: 7 TON | C15: Comamo (Cargo directo) | D15: 464 | E15: EX-6797 | F15: HELI | G15: CPCD70-CU1G3 | H15: 2024 | I15: MEGA CENTRO (COMACO) | J15: 151 | K15: 151.5 | L15: 233.9 | M15: 234.1 | N15: 236.6 | O15: 238.5 | P15: 238.5 | Q15: 238.8
A16: GRUA HORQUILLA (Diesel) | B16: 3 TON | C16: Comamo (Planta PAC) | D16: 459 | E16: EX-6798 | F16: HELI | G16: CPCD35-KU20H | H16: 2024 | I16: MEGA CENTRO (COMACO) | J16: 118 | K16: 118.6 | L16: 119 | M16: 120 | N16: 123.6 | O16: 123.8 | P16: 124
A17: GRUA HORQUILLA (Diesel) | B17: 3 TON | C17: Comamo (PC 1) | D17: 460 | E17: EX-6799 | F17: HELI | G17: CPCD35-KU20H | H17: 2024 | I17: MEGA CENTRO (COMACO) | J17: 151.1 | K17: 151.5 | L17: 152.4 | M17: 153.2 | N17: 153.9 | O17: 153.9 | P17: 153.9 | Q17: 155.3
A18: GRÚA HORQUILLA ELÉCTRICA | B18: 3,5 TON | C18: Comamo (Bodega principal) | D18: 475 | E18: EX-6800 | F18: HELI | G18: CPD35-GB2LI | H18: 2023 | I18: MEGA CENTRO (COMACO) | J18: 50 | K18: 50 | L18: 50 | M18: 53 | N18: 53 | O18: 54 | P18: 55
A19: GRÚA HORQUILLA ELÉCTRICA | B19: 2,5 TON | C19: Comamo ((PC 1) | D19: 467 | E19: EX-6801 | F19: HELI | G19: CPD25-GB2LI | H19: 2023 | I19: MEGA CENTRO (COMACO) | J19: 195 | K19: 196.7 | L19: 197 | M19: 198 | N19: 198 | O19: 198 | P19: 198
A20: TRACTO CAMIONES (RAMPLA) | B20: 28 TON | C20: RFP Logisitica | D20: VCYC-50 | E20: EX6832 | F20: MERCEDES BENZ | G20: ACTROZ | L20: 5584 | M20: 5625 | N20: 5625 | O20: 5625 | P20: 5625 | Q20: 5639
A21: TRACTO CAMIONES (RAMPLA) | B21: 28 TON | C21: RFP Logisitica | D21: VCYC-53 | E21: EX-6804 | F21: MERCEDES BENZ | G21: ACTROZ | L21: 6805 | M21: 6840 | N21: 6840 | O21: 6840 | P21: 6840
A22: TRACTO PARA CAMA BAJA 25 y 40 TON | B22: 25 TON | C22: RFP Logisitica | D22: VCYC-51 | E22: EX-6833 | F22: MERCEDES BENZ | G22: ACTROZ | H22: 2025 | L22: 9337 | M22: 9387 | N22: 9456 | O22: 9507 | P22: 9507 | Q22: 9387
A23: TRACTO PARA CAMA BAJA 25 y 40 TON | B23: 40 TON | C23: RFP Logisitica | D23: VCYC-52 | E23: EX-6834 | F23: MERCEDES BENZ | G23: ACTROZ | H23: 2025 | L23: 7543 | M23: 7585 | N23: 7622 | O23: 7656 | P23: 7742 | Q23: 7766
A24: TRACTO PARA CAMA BAJA 60 y 100 TON | B24: 60-100 TON | C24: RFP Logisitica | D24: HHBL-29 | E24: EX-6802 | F24: MERCEDES BENZ | G24: ACTROZ | L24: 227834 | M24: 227850 | N24: 227849 | O24: 227849 | P24: 227849
A25: CAMIÓN 10 TON | B25: 10 TON | C25: RFP Logisitica | D25: VFZG 96 | E25: EX-6836 | F25: MERCEDES BENZ | G25: FTR 1524 AMT | H25: 2022 | L25: 6014 | M25: 6030 | N25: 6445.6 | O25: 6445.6 | P25: 6445.6 | Q25: 6561
